2019-02-19 10:42:31,252 INFO: OJ startup [in C:\Users\WuBingting\Desktop\newoj\app\__init__.py:34]
2019-02-19 13:07:44,377 INFO: OJ startup [in C:\Users\WuBingting\Desktop\newoj\app\__init__.py:35]
2019-02-19 13:10:39,263 INFO: OJ startup [in C:\Users\WuBingting\Desktop\newoj\app\__init__.py:35]
2019-02-19 13:12:25,127 INFO: OJ startup [in C:\Users\WuBingting\Desktop\newoj\app\__init__.py:35]
2019-02-19 13:17:30,668 INFO: OJ startup [in C:\Users\WuBingting\Desktop\newoj\app\__init__.py:35]
2019-02-19 13:18:41,015 INFO: OJ startup [in C:\Users\WuBingting\Desktop\newoj\app\__init__.py:35]
2019-02-19 13:22:19,248 INFO: OJ startup [in C:\Users\WuBingting\Desktop\newoj\app\__init__.py:35]
2019-02-19 13:25:37,952 INFO: OJ startup [in C:\Users\WuBingting\Desktop\newoj\app\__init__.py:35]
2019-02-19 13:26:49,166 INFO: OJ startup [in C:\Users\WuBingting\Desktop\newoj\app\__init__.py:35]
2019-02-19 14:01:17,568 INFO: OJ startup [in C:\Users\WuBingting\Desktop\newoj\app\__init__.py:35]
2019-02-19 14:04:32,135 INFO: OJ startup [in C:\Users\WuBingting\Desktop\newoj\app\__init__.py:35]
2019-02-19 14:38:24,763 INFO: OJ startup [in C:\Users\WuBingting\Desktop\newoj\app\__init__.py:35]
2019-02-19 14:38:56,469 ERROR: Exception on /addproblem [POST] [in c:\users\wubingting\desktop\newoj\venv\lib\site-packages\flask\app.py:1761]
Traceback (most recent call last):
  File "c:\users\wubingting\desktop\newoj\venv\lib\site-packages\flask\app.py", line 2292, in wsgi_app
    response = self.full_dispatch_request()
  File "c:\users\wubingting\desktop\newoj\venv\lib\site-packages\flask\app.py", line 1815, in full_dispatch_request
    rv = self.handle_user_exception(e)
  File "c:\users\wubingting\desktop\newoj\venv\lib\site-packages\flask\app.py", line 1718, in handle_user_exception
    reraise(exc_type, exc_value, tb)
  File "c:\users\wubingting\desktop\newoj\venv\lib\site-packages\flask\_compat.py", line 35, in reraise
    raise value
  File "c:\users\wubingting\desktop\newoj\venv\lib\site-packages\flask\app.py", line 1813, in full_dispatch_request
    rv = self.dispatch_request()
  File "c:\users\wubingting\desktop\newoj\venv\lib\site-packages\flask\app.py", line 1799, in dispatch_request
    return self.view_functions[rule.endpoint](**req.view_args)
  File "C:\Users\WuBingting\Desktop\newoj\app\routes.py", line 255, in addproblem
    filename = secure_filename(f.filename)
NameError: name 'secure_filename' is not defined
2019-02-19 14:41:35,134 INFO: OJ startup [in C:\Users\WuBingting\Desktop\newoj\app\__init__.py:34]
2019-02-19 14:41:39,786 ERROR: Exception on /addproblem [POST] [in c:\users\wubingting\desktop\newoj\venv\lib\site-packages\flask\app.py:1761]
Traceback (most recent call last):
  File "c:\users\wubingting\desktop\newoj\venv\lib\site-packages\flask\app.py", line 2292, in wsgi_app
    response = self.full_dispatch_request()
  File "c:\users\wubingting\desktop\newoj\venv\lib\site-packages\flask\app.py", line 1815, in full_dispatch_request
    rv = self.handle_user_exception(e)
  File "c:\users\wubingting\desktop\newoj\venv\lib\site-packages\flask\app.py", line 1718, in handle_user_exception
    reraise(exc_type, exc_value, tb)
  File "c:\users\wubingting\desktop\newoj\venv\lib\site-packages\flask\_compat.py", line 35, in reraise
    raise value
  File "c:\users\wubingting\desktop\newoj\venv\lib\site-packages\flask\app.py", line 1813, in full_dispatch_request
    rv = self.dispatch_request()
  File "c:\users\wubingting\desktop\newoj\venv\lib\site-packages\flask\app.py", line 1799, in dispatch_request
    return self.view_functions[rule.endpoint](**req.view_args)
  File "C:\Users\WuBingting\Desktop\newoj\app\routes.py", line 256, in addproblem
    filename = secure_filename(f.filename)
NameError: name 'f' is not defined
2019-02-19 14:43:11,407 INFO: OJ startup [in C:\Users\WuBingting\Desktop\newoj\app\__init__.py:34]
2019-02-19 14:43:46,232 ERROR: Exception on /addproblem [POST] [in c:\users\wubingting\desktop\newoj\venv\lib\site-packages\flask\app.py:1761]
Traceback (most recent call last):
  File "c:\users\wubingting\desktop\newoj\venv\lib\site-packages\flask\app.py", line 2292, in wsgi_app
    response = self.full_dispatch_request()
  File "c:\users\wubingting\desktop\newoj\venv\lib\site-packages\flask\app.py", line 1815, in full_dispatch_request
    rv = self.handle_user_exception(e)
  File "c:\users\wubingting\desktop\newoj\venv\lib\site-packages\flask\app.py", line 1718, in handle_user_exception
    reraise(exc_type, exc_value, tb)
  File "c:\users\wubingting\desktop\newoj\venv\lib\site-packages\flask\_compat.py", line 35, in reraise
    raise value
  File "c:\users\wubingting\desktop\newoj\venv\lib\site-packages\flask\app.py", line 1813, in full_dispatch_request
    rv = self.dispatch_request()
  File "c:\users\wubingting\desktop\newoj\venv\lib\site-packages\flask\app.py", line 1799, in dispatch_request
    return self.view_functions[rule.endpoint](**req.view_args)
  File "C:\Users\WuBingting\Desktop\newoj\app\routes.py", line 257, in addproblem
    filename = secure_filename(f.filename)
AttributeError: 'str' object has no attribute 'filename'
2019-02-19 14:46:34,910 INFO: OJ startup [in C:\Users\WuBingting\Desktop\newoj\app\__init__.py:34]
2019-02-19 14:47:13,364 ERROR: Exception on /addproblem [POST] [in c:\users\wubingting\desktop\newoj\venv\lib\site-packages\flask\app.py:1761]
Traceback (most recent call last):
  File "c:\users\wubingting\desktop\newoj\venv\lib\site-packages\flask\app.py", line 2292, in wsgi_app
    response = self.full_dispatch_request()
  File "c:\users\wubingting\desktop\newoj\venv\lib\site-packages\flask\app.py", line 1815, in full_dispatch_request
    rv = self.handle_user_exception(e)
  File "c:\users\wubingting\desktop\newoj\venv\lib\site-packages\flask\app.py", line 1718, in handle_user_exception
    reraise(exc_type, exc_value, tb)
  File "c:\users\wubingting\desktop\newoj\venv\lib\site-packages\flask\_compat.py", line 35, in reraise
    raise value
  File "c:\users\wubingting\desktop\newoj\venv\lib\site-packages\flask\app.py", line 1813, in full_dispatch_request
    rv = self.dispatch_request()
  File "c:\users\wubingting\desktop\newoj\venv\lib\site-packages\flask\app.py", line 1799, in dispatch_request
    return self.view_functions[rule.endpoint](**req.view_args)
  File "C:\Users\WuBingting\Desktop\newoj\app\routes.py", line 257, in addproblem
    filename = secure_filename(form.stdin.data.filename)
AttributeError: 'str' object has no attribute 'filename'
2019-02-19 15:02:39,303 INFO: OJ startup [in C:\Users\WuBingting\Desktop\newoj\app\__init__.py:34]
2019-02-19 15:02:40,888 ERROR: Exception on /addproblem [POST] [in c:\users\wubingting\desktop\newoj\venv\lib\site-packages\flask\app.py:1761]
Traceback (most recent call last):
  File "c:\users\wubingting\desktop\newoj\venv\lib\site-packages\flask\app.py", line 2292, in wsgi_app
    response = self.full_dispatch_request()
  File "c:\users\wubingting\desktop\newoj\venv\lib\site-packages\flask\app.py", line 1815, in full_dispatch_request
    rv = self.handle_user_exception(e)
  File "c:\users\wubingting\desktop\newoj\venv\lib\site-packages\flask\app.py", line 1718, in handle_user_exception
    reraise(exc_type, exc_value, tb)
  File "c:\users\wubingting\desktop\newoj\venv\lib\site-packages\flask\_compat.py", line 35, in reraise
    raise value
  File "c:\users\wubingting\desktop\newoj\venv\lib\site-packages\flask\app.py", line 1813, in full_dispatch_request
    rv = self.dispatch_request()
  File "c:\users\wubingting\desktop\newoj\venv\lib\site-packages\flask\app.py", line 1799, in dispatch_request
    return self.view_functions[rule.endpoint](**req.view_args)
  File "C:\Users\WuBingting\Desktop\newoj\app\routes.py", line 256, in addproblem
    filename = form.stdin.data.filename
AttributeError: 'str' object has no attribute 'filename'
2019-02-19 15:03:44,344 ERROR: Exception on /addproblem [POST] [in c:\users\wubingting\desktop\newoj\venv\lib\site-packages\flask\app.py:1761]
Traceback (most recent call last):
  File "c:\users\wubingting\desktop\newoj\venv\lib\site-packages\flask\app.py", line 2292, in wsgi_app
    response = self.full_dispatch_request()
  File "c:\users\wubingting\desktop\newoj\venv\lib\site-packages\flask\app.py", line 1815, in full_dispatch_request
    rv = self.handle_user_exception(e)
  File "c:\users\wubingting\desktop\newoj\venv\lib\site-packages\flask\app.py", line 1718, in handle_user_exception
    reraise(exc_type, exc_value, tb)
  File "c:\users\wubingting\desktop\newoj\venv\lib\site-packages\flask\_compat.py", line 35, in reraise
    raise value
  File "c:\users\wubingting\desktop\newoj\venv\lib\site-packages\flask\app.py", line 1813, in full_dispatch_request
    rv = self.dispatch_request()
  File "c:\users\wubingting\desktop\newoj\venv\lib\site-packages\flask\app.py", line 1799, in dispatch_request
    return self.view_functions[rule.endpoint](**req.view_args)
  File "C:\Users\WuBingting\Desktop\newoj\app\routes.py", line 256, in addproblem
    filename = form.stdin.data.filename
AttributeError: 'str' object has no attribute 'filename'
2019-02-19 15:04:02,503 INFO: OJ startup [in C:\Users\WuBingting\Desktop\newoj\app\__init__.py:34]
